Workbook

Sheet RVN_0524
A1: Numero | B1: Seccion | C1: Reg | D1: Provincia | E1: Canton | F1: Distrito | G1: Ruta | H1: Jerarquia | I1: Red Vial Estrategica | J1: Rve Descripcion | K1: Longitud KM | L1: Longitud Acomulada | M1: Hor_Bueno | N1: Hor_Regular | O1: Hor_Malo | P1: Total | Q1: Ca_Buena | R1: Ca_Regular | S1: Ca_Mala | T1: Total | U1: Ts_Bueno | V1: Ts_Regular | W1: Ts_Malo | X1: Total | Y1: Tsi_Bueno | Z1: Tsi_Regular | AA1: Tsi_Malo | AB1: Total | AC1: Asfalto Total | AD1: Las_Bueno | AE1: Las_Regular | AF1: Las_Malo | AG1: Total | AH1: Tie_Buena | AI1: Tie_Regular | AJ1: Tie_Malo | AK1: Total | AL1: Otros_Buena | AM1: Otros_Regular | AN1: Otros_Malo | AO1: Total | AP1: SA_Buena | AQ1: SA_Regular | AR1: SA_Malo | AS1: Total | AT1: Mp_Buena | AU1: Mp_Regular | AV1: Mp_Malo | AW1: Total | AX1: Descripcion | AY1: Fecha Inv | AZ1: Fecha Rec | BA1: Derecho Via | BB1: Ptes Inadec | BC1: Tipo Terren | BD1: Terreno | BE1: Tipo Sup | BF1: Superficie | BG1: N° Car | BH1: Ancho Sup | BI1: Tipo Esp | BJ1: Espaldon | BK1: Ancho Esp | BL1: Vel | BM1: Tpda | BN1: Aline | BO1: Alineamiento | BP1: Pen | BQ1: Pendiente Descripcion | BR1: Visib | BS1: Esp | BT1: Espaldon Descripcion | BU1: Señal | BV1: Señalamiento Descripcion | BW1: Dren | BX1: Drenaje Descripcion | BY1: Sup | BZ1: Superficie Descripcion | CA1: Estruc Pav | CB1: Estructura Pavimento Descripcion | CC1: Veh Km | CD1: Estacion | CE1: Estacion Base | CF1: Ubicacion
A2: 23 | B2: 10001 | C2: 10 | D2: 1 | E2: 19 | F2: 3 | G2: 2 | H2: =IF(G2<100,"Primaria",IF(AND(G2>39,G2<300),"Secundaria",IF(AND(G2>299),"Terciaria"))) -> Primaria | I2: 1 | J2: =IF(I2=1,"Red de Alta Capacidad",IF(AND(I2=2),"Distribuidores Regionales",IF(AND(I2=3),"Conectores de Integración Territorial",IF(AND(I2=4),"Red Básica de Accesso")))) -> Red de Alta Capacidad | K2: =P2+$T2+$X2+$AB2+$AG2+$AK2+$AW2+AO2+AS2 -> 17.995 | L2: =L1+K2 -> 17.995 | P2: =SUM(M2:O2) -> 0 | Q2: 17.995 | T2: =SUM(Q2:S2) -> 17.995 | X2: =U2+V2+W2 -> 0 | AB2: =Y2+Z2+AA2 -> 0 | AC2: =T2+X2+AB2 -> 17.995 | AG2: =SUM(AD2:AF2) -> 0 | AK2: =SUM(AH2:AJ2) -> 0 | AO2: =SUM(AL2:AN2) -> 0 | AS2: =SUM(AP2:AR2) -> 0 | AW2: =SUM(AT2:AV2) -> 0 | AX2: Juntas De Pacuar(R.244)-Convento (Río Convento)(Lte Provincial) | AY2: 10/14 | AZ2: 05/17 | BA2: 50.0 | BB2: 0 | BC2: 3 | BD2: =IF(BC2=1,"Llano (Pendientes naturales del terreno entre 0 y 5%)",IF(AND(BC2=2),"Algo Ondulado (Pendientes naturales del terreno entre 6 y 14%)",IF(AND(BC2=3),"Muy Ondulado (Pendientes naturales del terreno entre 15 y 25%)",IF(AND(BC2=4),"Montañoso (Pendientes naturales del terreno mayores a 25%)")))) -> Muy Ondulado (Pendientes naturales del terreno entre 15 y 25%) | BE2: 1 | BF2: =VLOOKUP(BE2,'Códigos 2'!$A$1:$B$12,2,FALSE) -> Carpeta Asfáltica (CA) | BG2: 2 | BH2: 6.9 | BI2: 1 | BJ2: =IF(BI2=0,"No existe",IF(AND(BI2=1),"Pavimentado",IF(AND(BI2=2),"Mejorado",IF(AND(BI2=3),"Tierra")))) -> Pavimentado | BK2: 1 | BL2: 60 | BM2: 3700 | BN2: 4 | BO2: =IF(BN2=5,"Alineamiento recto o con curvas tan suaves que no exigen una reducción significativa en la velocidad promedio normal de recorrido.",IF(AND(BN2=4),"Alineamiento con algunas curvas que exigen una reducción significativa en la velocidad promedio de circulación.",IF(AND(BN2=3),"Alineamiento algo sinuoso, pero con curvas cerradas que son aparentes y consistentes con las gradientes y las demás características del camino y del terreno que se atraviesa.",IF(AND(BN2=2),"Curvas cerradas frecuentes y, por lo general, inconsistentes con el terreno y la clase de carretera.",IF(AND(BN2=1),"Alineamiento muy sinuoso en todo el tramo, condición que admite solamente una velocidad de circulación muy baja."))))) -> Alineamiento con algunas curvas que exigen una reducción significativa en la velocidad promedio de circulación. | BP2: 2 | BQ2: =IF(BP2=5,"Pendientes menores del 3% en todo el tramo.",IF(AND(BP2=4),"Pendientes generalmente menores del 3% pero con algunas cuestas de corta longitud de hasta el 5%.",IF(AND(BP2=3),"Pendientes generalmente entre 3 y 6%, pero con una rasante ondulada y, consecuentemente, con tramos cortos de subida fuerte.",IF(AND(BP2=2),"Pendientes sostenidas entre 5 y 8% sobre una buena parte del tramo, condición que afecta en forma marcada la velocidad de recorrido y, cuando hay bastante tránsito, provoca frecuentes colas de vehículos detrás de los vehículos pesados.",IF(AND(BP2=1),"Pendientes sostenidas en exceso del 7% en casi todo el tramo. "))))) -> Pendientes sostenidas entre 5 y 8% sobre una buena parte del tramo, condición que afecta en forma marcada la velocidad de recorrido y, cuando hay bastante tránsito, provoca frecuentes colas de vehículos detrás de los vehículos pesados. | BR2: 1 | BS2: 5 | BT2: =IF(BS2=5,"Superficie de los espaldones firme y regular, y donde se puede utilizar el ancho como fue construido originalmente.",IF(AND(BS2=4),"Superficie generalmente firme y utilizable en todo tiempo, pero con algunos tramos cortos en que el ancho inicial ha sido reducido por erosión u otras causas.",IF(AND(BS2=3),"Superficie erosionada o con baches profundos sobre una buena parte de la subsección, de manera que se inhibe el uso de los espaldones en la debida forma en esa parte.",IF(AND(BS2=2),"Superficie erosionada o con baches profundos, o el ancho transitable de los espaldones reducido sustancialmente, en casi toda la subsección.",IF(AND(BS2=1),"Se encuentra un desnivel peligroso entre el borde del pavimento y el espaldón, o la superficie está muy erosionada, con baches profundos o material suelto, o el ancho muy reducido del original."))))) -> Superficie de los espaldones firme y regular, y donde se puede utilizar el ancho como fue construido originalmente. | BU2: 4 | BV2: =IF(BU2=5,"Las señales son completamente adecuadas en número y ubicación, ",IF(AND(BU2=4),"El señalamiento es bastante completo, faltando solamente algunas señales de guía para los usuarios que no conocen la ruta.",IF(AND(BU2=3),"El señalamiento es regular en cuanto a cantidad y ubicación, siendo notable la falta de algunas señales de precaución y de guía.",IF(AND(BU2=2),"Existen muy pocas señales",IF(AND(BU2=1),"No existen señales o son tan inadecuadas, que no proveen información útil al conductor."))))) -> El señalamiento es bastante completo, faltando solamente algunas señales de guía para los usuarios que no conocen la ruta. | BW2: 5 | BX2: =IF(BW2=5,"Todas las alcantarillas y cunetas están bastante limpias y funcionan debidamente.",IF(AND(BW2=4),"La mayoría de las alcantarillas y cunetas aparentemente funcionan bien, pero existen indicaciones en algunos sitios de que el agua se estanca.",IF(AND(BW2=3),"Parece que algunas alcantarillas o cunetas no tienen capacidad hidráulica suficiente, por la erosión o socavación aparente.",IF(AND(BW2=2),"Parece que la mayoría de las alcantarillas y cunetas son inadecuadas; o hay vados en varios sitios en vez de estructuras de drenaje.",IF(AND(BW2=1),"El agua escurre por la calzada durante períodos de lluvia sobre una buena parte de la sub-sección y no existen cunetas longitudinales definidas; las estructuras de drenaje no existen, o son completamente inadecuadas."))))) -> Todas las alcantarillas y cunetas están bastante limpias y funcionan debidamente. | BY2: 4 | BZ2: =IF(BY2=5,"Superficie lisa, sin baches ni irregularidades notables.",IF(AND(BY2=4),"Superficie generalmente lisa, pero con unas pequeñas corrugaciones u otras irregularidades aisladas, o con baches pequeños superficiales.",IF(AND(BY2=3),"Superficie con frecuentes baches o irregularidades .",IF(AND(BY2=2),"Superficie muy irregular o con baches extensos y frecuentes (o material suelto, en caso de superficies no pavimentadas).",IF(AND(BY2=1),"Superficie muy deteriorada o irregular (o material suelto), hasta tal grado, en casi todo el tramo."))))) -> Superficie generalmente lisa, pero con unas pequeñas corrugaciones u otras irregularidades aisladas, o con baches pequeños superficiales. | CA2: 5 | CB2: =IF(CA2=5,"No existen evidencias de fallas en la estructura del pavimento, con la posible excepción de algunas en la superficie de ruedo.",IF(AND(CA2=4),"Existen huellas o corrugaciones que se derivan por debajo de la superficie de ruedo, pero que son aisladas y de poca extensión.",IF(AND(CA2=3),"Existen deformaciones u otras fallas de consideración sobre una buena parte de la subsección y, aunque no son extensas todavía, parece que siguen extendiéndose.",IF(AND(CA2=2),"Existen deformaciones u otras fallas de consideración sobre la mayor parte del tramo.",IF(AND(CA2=1),"Existen corrugaciones o huellas profundas sobre casi toda la faja de ruedo del tramo, hasta tal grado que no sería factible corregir la falla de la estructura, sino que se tendría que reconstruirla completamente."))))) -> No existen evidencias de fallas en la estructura del pavimento, con la posible excepción de algunas en la superficie de ruedo. | CC2: =(K2*BM2)*365/1000000 -> 24.302248 | CF2: *lectura km 159+700(fecha: miercoles 10/12/2012)
A3: 22 | B3: 10002 | C3: 10 | D3: 1 | E3: 19 | F3: 3 | G3: 2 | H3: =IF(G3<100,"Primaria",IF(AND(G3>39,G3<300),"Secundaria",IF(AND(G3>299),"Terciaria"))) -> Primaria | I3: 1 | J3: =IF(I3=1,"Red de Alta Capacidad",IF(AND(I3=2),"Distribuidores Regionales",IF(AND(I3=3),"Conectores de Integración Territorial",IF(AND(I3=4),"Red Básica de Accesso")))) -> Red de Alta Capacidad | K3: =P3+$T3+$X3+$AB3+$AG3+$AK3+$AW3+AO3+AS3 -> 6.89 | L3: =L2+K3 -> 24.885 | P3: =SUM(M3:O3) -> 0 | Q3: 6.89 | T3: =SUM(Q3:S3) -> 6.89 | X3: =U3+V3+W3 -> 0 | AB3: =Y3+Z3+AA3 -> 0 | AC3: =T3+X3+AB3 -> 6.89 | AG3: =SUM(AD3:AF3) -> 0 | AK3: =SUM(AH3:AJ3) -> 0 | AO3: =SUM(AL3:AN3) -> 0 | AS3: =SUM(AP3:AR3) -> 0 | AW3: =SUM(AT3:AV3) -> 0 | AX3: Palmares(Final Cinco Carriles)-Juntas De Pacuar(R.244) | AY3: 10/14 | AZ3: 05/17 | BA3: 50.0 | BB3: 0 | BC3: 1 | BD3: =IF(BC3=1,"Llano (Pendientes naturales del terreno entre 0 y 5%)",IF(AND(BC3=2),"Algo Ondulado (Pendientes naturales del terreno entre 6 y 14%)",IF(AND(BC3=3),"Muy Ondulado (Pendientes naturales del terreno entre 15 y 25%)",IF(AND(BC3=4),"Montañoso (Pendientes naturales del terreno mayores a 25%)")))) -> Llano (Pendientes naturales del terreno entre 0 y 5%) | BE3: 1 | BF3: =VLOOKUP(BE3,'Códigos 2'!$A$1:$B$12,2,FALSE) -> Carpeta Asfáltica (CA) | BG3: 2 | BH3: 7 | BI3: 1 | BJ3: =IF(BI3=0,"No existe",IF(AND(BI3=1),"Pavimentado",IF(AND(BI3=2),"Mejorado",IF(AND(BI3=3),"Tierra")))) -> Pavimentado | BK3: 1.1 | BL3: 60 | BN3: 4 | BO3: =IF(BN3=5,"Alineamiento recto o con curvas tan suaves que no exigen una reducción significativa en la velocidad promedio normal de recorrido.",IF(AND(BN3=4),"Alineamiento con algunas curvas que exigen una reducción significativa en la velocidad promedio de circulación.",IF(AND(BN3=3),"Alineamiento algo sinuoso, pero con curvas cerradas que son aparentes y consistentes con las gradientes y las demás características del camino y del terreno que se atraviesa.",IF(AND(BN3=2),"Curvas cerradas frecuentes y, por lo general, inconsistentes con el terreno y la clase de carretera.",IF(AND(BN3=1),"Alineamiento muy sinuoso en todo el tramo, condición que admite solamente una velocidad de circulación muy baja."))))) -> Alineamiento con algunas curvas que exigen una reducción significativa en la velocidad promedio de circulación. | BP3: 4 | BQ3: =IF(BP3=5,"Pendientes menores del 3% en todo el tramo.",IF(AND(BP3=4),"Pendientes generalmente menores del 3% pero con algunas cuestas de corta longitud de hasta el 5%.",IF(AND(BP3=3),"Pendientes generalmente entre 3 y 6%, pero con una rasante ondulada y, consecuentemente, con tramos cortos de subida fuerte.",IF(AND(BP3=2),"Pendientes sostenidas entre 5 y 8% sobre una buena parte del tramo, condición que afecta en forma marcada la velocidad de recorrido y, cuando hay bastante tránsito, provoca frecuentes colas de vehículos detrás de los vehículos pesados.",IF(AND(BP3=1),"Pendientes sostenidas en exceso del 7% en casi todo el tramo. "))))) -> Pendientes generalmente menores del 3% pero con algunas cuestas de corta longitud de hasta el 5%. | BR3: 2 | BS3: 5 | BT3: =IF(BS3=5,"Superficie de los espaldones firme y regular, y donde se puede utilizar el ancho como fue construido originalmente.",IF(AND(BS3=4),"Superficie generalmente firme y utilizable en todo tiempo, pero con algunos tramos cortos en que el ancho inicial ha sido reducido por erosión u otras causas.",IF(AND(BS3=3),"Superficie erosionada o con baches profundos sobre una buena parte de la subsección, de manera que se inhibe el uso de los espaldones en la debida forma en esa parte.",IF(AND(BS3=2),"Superficie erosionada o con baches profundos, o el ancho transitable de los espaldones reducido sustancialmente, en casi toda la subsección.",IF(AND(BS3=1),"Se encuentra un desnivel peligroso entre el borde del pavimento y el espaldón, o la superficie está muy erosionada, con baches profundos o material suelto, o el ancho muy reducido del original."))))) -> Superficie de los espaldones firme y regular, y donde se puede utilizar el ancho como fue construido originalmente. | BU3: 5 | BV3: =IF(BU3=5,"Las señales son completamente adecuadas en número y ubicación, ",IF(AND(BU3=4),"El señalamiento es bastante completo, faltando solamente algunas señales de guía para los usuarios que no conocen la ruta.",IF(AND(BU3=3),"El señalamiento es regular en cuanto a cantidad y ubicación, siendo notable la falta de algunas señales de precaución y de guía.",IF(AND(BU3=2),"Existen muy pocas señales",IF(AND(BU3=1),"No existen señales o son tan inadecuadas, que no proveen información útil al conductor."))))) -> Las señales son completamente adecuadas en número y ubicación, | BW3: 5 | BX3: =IF(BW3=5,"Todas las alcantarillas y cunetas están bastante limpias y funcionan debidamente.",IF(AND(BW3=4),"La mayoría de las alcantarillas y cunetas aparentemente funcionan bien, pero existen indicaciones en algunos sitios de que el agua se estanca.",IF(AND(BW3=3),"Parece que algunas alcantarillas o cunetas no tienen capacidad hidráulica suficiente, por la erosión o socavación aparente.",IF(AND(BW3=2),"Parece que la mayoría de las alcantarillas y cunetas son inadecuadas; o hay vados en varios sitios en vez de estructuras de drenaje.",IF(AND(BW3=1),"El agua escurre por la calzada durante períodos de lluvia sobre una buena parte de la sub-sección y no existen cunetas longitudinales definidas; las estructuras de drenaje no existen, o son completamente inadecuadas."))))) -> Todas las alcantarillas y cunetas están bastante limpias y funcionan debidamente. | BY3: 4 | BZ3: =IF(BY3=5,"Superficie lisa, sin baches ni irregularidades notables.",IF(AND(BY3=4),"Superficie generalmente lisa, pero con unas pequeñas corrugaciones u otras irregularidades aisladas, o con baches pequeños superficiales.",IF(AND(BY3=3),"Superficie con frecuentes baches o irregularidades .",IF(AND(BY3=2),"Superficie muy irregular o con baches extensos y frecuentes (o material suelto, en caso de superficies no pavimentadas).",IF(AND(BY3=1),"Superficie muy deteriorada o irregular (o material suelto), hasta tal grado, en casi todo el tramo."))))) -> Superficie generalmente lisa, pero con unas pequeñas corrugaciones u otras irregularidades aisladas, o con baches pequeños superficiales. | CA3: 5 | CB3: =IF(CA3=5,"No existen evidencias de fallas en la estructura del pavimento, con la posible excepción de algunas en la superficie de ruedo.",IF(AND(CA3=4),"Existen huellas o corrugaciones que se derivan por debajo de la superficie de ruedo, pero que son aisladas y de poca extensión.",IF(AND(CA3=3),"Existen deformaciones u otras fallas de consideración sobre una buena parte de la subsección y, aunque no son extensas todavía, parece que siguen extendiéndose.",IF(AND(CA3=2),"Existen deformaciones u otras fallas de consideración sobre la mayor parte del tramo.",IF(AND(CA3=1),"Existen corrugaciones o huellas profundas sobre casi toda la faja de ruedo del tramo, hasta tal grado que no sería factible corregir la falla de la estructura, sino que se tendría que reconstruirla completamente."))))) -> No existen evidencias de fallas en la estructura del pavimento, con la posible excepción de algunas en la superficie de ruedo. | CC3: =(K3*BM3)*365/1000000 -> 0 | CD3: 706 | CE3: 7 | CF3: PALMARES(0+100 MTS DESPUES ENTRADA COLEGIO ALFREDO VOLIO)
A4: 21 | B4: 10003 | C4: 10 | D4: 1 | E4: 19 | F4: 1 | G4: 2 | H4: =IF(G4<100,"Primaria",IF(AND(G4>39,G4<300),"Secundaria",IF(AND(G4>299),"Terciaria"))) -> Primaria | I4: 1 | J4: =IF(I4=1,"Red de Alta Capacidad",IF(AND(I4=2),"Distribuidores Regionales",IF(AND(I4=3),"Conectores de Integración Territorial",IF(AND(I4=4),"Red Básica de Accesso")))) -> Red de Alta Capacidad | K4: =P4+$T4+$X4+$AB4+$AG4+$AK4+$AW4+AO4+AS4 -> 7.915 | L4: =L3+K4 -> 32.8 | P4: =SUM(M4:O4) -> 0 | Q4: 7.915 | T4: =SUM(Q4:S4) -> 7.915 | X4: =U4+V4+W4 -> 0 | AB4: =Y4+Z4+AA4 -> 0 | AC4: =T4+X4+AB4 -> 7.915 | AG4: =SUM(AD4:AF4) -> 0 | AK4: =SUM(AH4:AJ4) -> 0 | AO4: =SUM(AL4:AN4) -> 0 | AS4: =SUM(AP4:AR4) -> 0 | AW4: =SUM(AT4:AV4) -> 0 | AX4: San Isidro Peréz Zeledón(R.243)-Palmares(Final Cinco Carriles) | AY4: 10/14 | AZ4: 05/17 | BA4: 29,8-50,0 | BB4: 0 | BC4: 1 | BD4: =IF(BC4=1,"Llano (Pendientes naturales del terreno entre 0 y 5%)",IF(AND(BC4=2),"Algo Ondulado (Pendientes naturales del terreno entre 6 y 14%)",IF(AND(BC4=3),"Muy Ondulado (Pendientes naturales del terreno entre 15 y 25%)",IF(AND(BC4=4),"Montañoso (Pendientes naturales del terreno mayores a 25%)")))) -> Llano (Pendientes naturales del terreno entre 0 y 5%) | BE4: 1 | BF4: =VLOOKUP(BE4,'Códigos 2'!$A$1:$B$12,2,FALSE) -> Carpeta Asfáltica (CA) | BG4: 5 | BH4: 15.1 | BI4: 1 | BJ4: =IF(BI4=0,"No existe",IF(AND(BI4=1),"Pavimentado",IF(AND(BI4=2),"Mejorado",IF(AND(BI4=3),"Tierra")))) -> Pavimentado | BK4: 0.9 | BL4: 60 | BM4: 17452 | BN4: 5 | BO4: =IF(BN4=5,"Alineamiento recto o con curvas tan suaves que no exigen una reducción significativa en la velocidad promedio normal de recorrido.",IF(AND(BN4=4),"Alineamiento con algunas curvas que exigen una reducción significativa en la velocidad promedio de circulación.",IF(AND(BN4=3),"Alineamiento algo sinuoso, pero con curvas cerradas que son aparentes y consistentes con las gradientes y las demás características del camino y del terreno que se atraviesa.",IF(AND(BN4=2),"Curvas cerradas frecuentes y, por lo general, inconsistentes con el terreno y la clase de carretera.",IF(AND(BN4=1),"Alineamiento muy sinuoso en todo el tramo, condición que admite solamente una velocidad de circulación muy baja."))))) -> Alineamiento recto o con curvas tan suaves que no exigen una reducción significativa en la velocidad promedio normal de recorrido. | BP4: 4 | BQ4: =IF(BP4=5,"Pendientes menores del 3% en todo el tramo.",IF(AND(BP4=4),"Pendientes generalmente menores del 3% pero con algunas cuestas de corta longitud de hasta el 5%.",IF(AND(BP4=3),"Pendientes generalmente entre 3 y 6%, pero con una rasante ondulada y, consecuentemente, con tramos cortos de subida fuerte.",IF(AND(BP4=2),"Pendientes sostenidas entre 5 y 8% sobre una buena parte del tramo, condición que afecta en forma marcada la velocidad de recorrido y, cuando hay bastante tránsito, provoca frecuentes colas de vehículos detrás de los vehículos pesados.",IF(AND(BP4=1),"Pendientes sostenidas en exceso del 7% en casi todo el tramo. "))))) -> Pendientes generalmente menores del 3% pero con algunas cuestas de corta longitud de hasta el 5%. | BR4: 5 | BS4: 5 | BT4: =IF(BS4=5,"Superficie de los espaldones firme y regular, y donde se puede utilizar el ancho como fue construido originalmente.",IF(AND(BS4=4),"Superficie generalmente firme y utilizable en todo tiempo, pero con algunos tramos cortos en que el ancho inicial ha sido reducido por erosión u otras causas.",IF(AND(BS4=3),"Superficie erosionada o con baches profundos sobre una buena parte de la subsección, de manera que se inhibe el uso de los espaldones en la debida forma en esa parte.",IF(AND(BS4=2),"Superficie erosionada o con baches profundos, o el ancho transitable de los espaldones reducido sustancialmente, en casi toda la subsección.",IF(AND(BS4=1),"Se encuentra un desnivel peligroso entre el borde del pavimento y el espaldón, o la superficie está muy erosionada, con baches profundos o material suelto, o el ancho muy reducido del original."))))) -> Superficie de los espaldones firme y regular, y donde se puede utilizar el ancho como fue construido originalmente. | BU4: 5 | BV4: =IF(BU4=5,"Las señales son completamente adecuadas en número y ubicación, ",IF(AND(BU4=4),"El señalamiento es bastante completo, faltando solamente algunas señales de guía para los usuarios que no conocen la ruta.",IF(AND(BU4=3),"El señalamiento es regular en cuanto a cantidad y ubicación, siendo notable la falta de algunas señales de precaución y de guía.",IF(AND(BU4=2),"Existen muy pocas señales",IF(AND(BU4=1),"No existen señales o son tan inadecuadas, que no proveen información útil al conductor."))))) -> Las señales son completamente adecuadas en número y ubicación, | BW4: 5 | BX4: =IF(BW4=5,"Todas las alcantarillas y cunetas están bastante limpias y funcionan debidamente.",IF(AND(BW4=4),"La mayoría de las alcantarillas y cunetas aparentemente funcionan bien, pero existen indicaciones en algunos sitios de que el agua se estanca.",IF(AND(BW4=3),"Parece que algunas alcantarillas o cunetas no tienen capacidad hidráulica suficiente, por la erosión o socavación aparente.",IF(AND(BW4=2),"Parece que la mayoría de las alcantarillas y cunetas son inadecuadas; o hay vados en varios sitios en vez de estructuras de drenaje.",IF(AND(BW4=1),"El agua escurre por la calzada durante períodos de lluvia sobre una buena parte de la sub-sección y no existen cunetas longitudinales definidas; las estructuras de drenaje no existen, o son completamente inadecuadas."))))) -> Todas las alcantarillas y cunetas están bastante limpias y funcionan debidamente. | BY4: 4 | BZ4: =IF(BY4=5,"Superficie lisa, sin baches ni irregularidades notables.",IF(AND(BY4=4),"Superficie generalmente lisa, pero con unas pequeñas corrugaciones u otras irregularidades aisladas, o con baches pequeños superficiales.",IF(AND(BY4=3),"Superficie con frecuentes baches o irregularidades .",IF(AND(BY4=2),"Superficie muy irregular o con baches extensos y frecuentes (o material suelto, en caso de superficies no pavimentadas).",IF(AND(BY4=1),"Superficie muy deteriorada o irregular (o material suelto), hasta tal grado, en casi todo el tramo."))))) -> Superficie generalmente lisa, pero con unas pequeñas corrugaciones u otras irregularidades aisladas, o con baches pequeños superficiales. | CA4: 5 | CB4: =IF(CA4=5,"No existen evidencias de fallas en la estructura del pavimento, con la posible excepción de algunas en la superficie de ruedo.",IF(AND(CA4=4),"Existen huellas o corrugaciones que se derivan por debajo de la superficie de ruedo, pero que son aisladas y de poca extensión.",IF(AND(CA4=3),"Existen deformaciones u otras fallas de consideración sobre una buena parte de la subsección y, aunque no son extensas todavía, parece que siguen extendiéndose.",IF(AND(CA4=2),"Existen deformaciones u otras fallas de consideración sobre la mayor parte del tramo.",IF(AND(CA4=1),"Existen corrugaciones o huellas profundas sobre casi toda la faja de ruedo del tramo, hasta tal grado que no sería factible corregir la falla de la estructura, sino que se tendría que reconstruirla completamente."))))) -> No existen evidencias de fallas en la estructura del pavimento, con la posible excepción de algunas en la superficie de ruedo. | CC4: =(K4*BM4)*365/1000000 -> 50.418392
A5: 20 | B5: 10010 | C5: 10 | D5: 1 | E5: 19 | F5: 11 | G5: 2 | H5: =IF(G5<100,"Primaria",IF(AND(G5>39,G5<300),"Secundaria",IF(AND(G5>299),"Terciaria"))) -> Primaria | I5: 1 | J5: =IF(I5=1,"Red de Alta Capacidad",IF(AND(I5=2),"Distribuidores Regionales",IF(AND(I5=3),"Conectores de Integración Territorial",IF(AND(I5=4),"Red Básica de Accesso")))) -> Red de Alta Capacidad | K5: =P5+$T5+$X5+$AB5+$AG5+$AK5+$AW5+AO5+AS5 -> 10.29 | L5: =L4+K5 -> 43.09 | P5: =SUM(M5:O5) -> 0 | Q5: 10.29 | T5: =SUM(Q5:S5) -> 10.29 | X5: =U5+V5+W5 -> 0 | AB5: =Y5+Z5+AA5 -> 0 | AC5: =T5+X5+AB5 -> 10.29 | AG5: =SUM(AD5:AF5) -> 0 | AK5: =SUM(AH5:AJ5) -> 0 | AO5: =SUM(AL5:AN5) -> 0 | AS5: =SUM(AP5:AR5) -> 0 | AW5: =SUM(AT5:AV5) -> 0 | AX5: La Ese(Escuela)-San Isidro De Peréz Zeledón (Ruta 243) | AY5: 10/14 | AZ5: 05/17 | BA5: 30 - 50 | BB5: 0 | BC5: 4 | BD5: =IF(BC5=1,"Llano (Pendientes naturales del terreno entre 0 y 5%)",IF(AND(BC5=2),"Algo Ondulado (Pendientes naturales del terreno entre 6 y 14%)",IF(AND(BC5=3),"Muy Ondulado (Pendientes naturales del terreno entre 15 y 25%)",IF(AND(BC5=4),"Montañoso (Pendientes naturales del terreno mayores a 25%)")))) -> Montañoso (Pendientes naturales del terreno mayores a 25%) | BE5: 1 | BF5: =VLOOKUP(BE5,'Códigos 2'!$A$1:$B$12,2,FALSE) -> Carpeta Asfáltica (CA) | BG5: 2 | BH5: 6.2 | BI5: 0 | BJ5: =IF(BI5=0,"No existe",IF(AND(BI5=1),"Pavimentado",IF(AND(BI5=2),"Mejorado",IF(AND(BI5=3),"Tierra")))) -> No existe | BK5: 0 | BL5: 50 | BM5: 3470 | BN5: 3 | BO5: =IF(BN5=5,"Alineamiento recto o con curvas tan suaves que no exigen una reducción significativa en la velocidad promedio normal de recorrido.",IF(AND(BN5=4),"Alineamiento con algunas curvas que exigen una reducción significativa en la velocidad promedio de circulación.",IF(AND(BN5=3),"Alineamiento algo sinuoso, pero con curvas cerradas que son aparentes y consistentes con las gradientes y las demás características del camino y del terreno que se atraviesa.",IF(AND(BN5=2),"Curvas cerradas frecuentes y, por lo general, inconsistentes con el terreno y la clase de carretera.",IF(AND(BN5=1),"Alineamiento muy sinuoso en todo el tramo, condición que admite solamente una velocidad de circulación muy baja."))))) -> Alineamiento algo sinuoso, pero con curvas cerradas que son aparentes y consistentes con las gradientes y las demás características del camino y del terreno que se atraviesa. | BP5: 1 | BQ5: =IF(BP5=5,"Pendientes menores del 3% en todo el tramo.",IF(AND(BP5=4),"Pendientes generalmente menores del 3% pero con algunas cuestas de corta longitud de hasta el 5%.",IF(AND(BP5=3),"Pendientes generalmente entre 3 y 6%, pero con una rasante ondulada y, consecuentemente, con tramos cortos de subida fuerte.",IF(AND(BP5=2),"Pendientes sostenidas entre 5 y 8% sobre una buena parte del tramo, condición que afecta en forma marcada la velocidad de recorrido y, cuando hay bastante tránsito, provoca frecuentes colas de vehículos detrás de los vehículos pesados.",IF(AND(BP5=1),"Pendientes sostenidas en exceso del 7% en casi todo el tramo. "))))) -> Pendientes sostenidas en exceso del 7% en casi todo el tramo. | BR5: 1 | BS5: 0 | BT5: =IF(BS5=5,"Superficie de los espaldones firme y regular, y donde se puede utilizar el ancho como fue construido originalmente.",IF(AND(BS5=4),"Superficie generalmente firme y utilizable en todo tiempo, pero con algunos tramos cortos en que el ancho inicial ha sido reducido por erosión u otras causas.",IF(AND(BS5=3),"Superficie erosionada o con baches profundos sobre una buena parte de la subsección, de manera que se inhibe el uso de los espaldones en la debida forma en esa parte.",IF(AND(BS5=2),"Superficie erosionada o con baches profundos, o el ancho transitable de los espaldones reducido sustancialmente, en casi toda la subsección.",IF(AND(BS5=1),"Se encuentra un desnivel peligroso entre el borde del pavimento y el espaldón, o la superficie está muy erosionada, con baches profundos o material suelto, o el ancho muy reducido del original."))))) -> FALSE | BU5: 5 | BV5: =IF(BU5=5,"Las señales son completamente adecuadas en número y ubicación, ",IF(AND(BU5=4),"El señalamiento es bastante completo, faltando solamente algunas señales de guía para los usuarios que no conocen la ruta.",IF(AND(BU5=3),"El señalamiento es regular en cuanto a cantidad y ubicación, siendo notable la falta de algunas señales de precaución y de guía.",IF(AND(BU5=2),"Existen muy pocas señales",IF(AND(BU5=1),"No existen señales o son tan inadecuadas, que no proveen información útil al conductor."))))) -> Las señales son completamente adecuadas en número y ubicación, | BW5: 4 | BX5: =IF(BW5=5,"Todas las alcantarillas y cunetas están bastante limpias y funcionan debidamente.",IF(AND(BW5=4),"La mayoría de las alcantarillas y cunetas aparentemente funcionan bien, pero existen indicaciones en algunos sitios de que el agua se estanca.",IF(AND(BW5=3),"Parece que algunas alcantarillas o cunetas no tienen capacidad hidráulica suficiente, por la erosión o socavación aparente.",IF(AND(BW5=2),"Parece que la mayoría de las alcantarillas y cunetas son inadecuadas; o hay vados en varios sitios en vez de estructuras de drenaje.",IF(AND(BW5=1),"El agua escurre por la calzada durante períodos de lluvia sobre una buena parte de la sub-sección y no existen cunetas longitudinales definidas; las estructuras de drenaje no existen, o son completamente inadecuadas."))))) -> La mayoría de las alcantarillas y cunetas aparentemente funcionan bien, pero existen indicaciones en algunos sitios de que el agua se estanca. | BY5: 5 | BZ5: =IF(BY5=5,"Superficie lisa, sin baches ni irregularidades notables.",IF(AND(BY5=4),"Superficie generalmente lisa, pero con unas pequeñas corrugaciones u otras irregularidades aisladas, o con baches pequeños superficiales.",IF(AND(BY5=3),"Superficie con frecuentes baches o irregularidades .",IF(AND(BY5=2),"Superficie muy irregular o con baches extensos y frecuentes (o material suelto, en caso de superficies no pavimentadas).",IF(AND(BY5=1),"Superficie muy deteriorada o irregular (o material suelto), hasta tal grado, en casi todo el tramo."))))) -> Superficie lisa, sin baches ni irregularidades notables. | CA5: 5 | CB5: =IF(CA5=5,"No existen evidencias de fallas en la estructura del pavimento, con la posible excepción de algunas en la superficie de ruedo.",IF(AND(CA5=4),"Existen huellas o corrugaciones que se derivan por debajo de la superficie de ruedo, pero que son aisladas y de poca extensión.",IF(AND(CA5=3),"Existen deformaciones u otras fallas de consideración sobre una buena parte de la subsección y, aunque no son extensas todavía, parece que siguen extendiéndose.",IF(AND(CA5=2),"Existen deformaciones u otras fallas de consideración sobre la mayor parte del tramo.",IF(AND(CA5=1),"Existen corrugaciones o huellas profundas sobre casi toda la faja de ruedo del tramo, hasta tal grado que no sería factible corregir la falla de la estructura, sino que se tendría que reconstruirla completamente."))))) -> No existen evidencias de fallas en la estructura del pavimento, con la posible excepción de algunas en la superficie de ruedo. | CC5: =(K5*BM5)*365/1000000 -> 13.032799 | CD5: 709 | CE5: 7 | CF5: A 1+000 KM ANTES TANQUES DE A Y A
A6: 19 | B6: 10020 | C6: 10 | D6: 1 | E6: 19 | F6: 11 | G6: 2 | H6: =IF(G6<100,"Primaria",IF(AND(G6>39,G6<300),"Secundaria",IF(AND(G6>299),"Terciaria"))) -> Primaria | I6: 1 | J6: =IF(I6=1,"Red de Alta Capacidad",IF(AND(I6=2),"Distribuidores Regionales",IF(AND(I6=3),"Conectores de Integración Territorial",IF(AND(I6=4),"Red Básica de Accesso")))) -> Red de Alta Capacidad | K6: =P6+$T6+$X6+$AB6+$AG6+$AK6+$AW6+AO6+AS6 -> 26.16 | L6: =L5+K6 -> 69.25 | P6: =SUM(M6:O6) -> 0 | Q6: 26.16 | T6: =SUM(Q6:S6) -> 26.16 | X6: =U6+V6+W6 -> 0 | AB6: =Y6+Z6+AA6 -> 0 | AC6: =T6+X6+AB6 -> 26.16 | AG6: =SUM(AD6:AF6) -> 0 | AK6: =SUM(AH6:AJ6) -> 0 | AO6: =SUM(AL6:AN6) -> 0 | AS6: =SUM(AP6:AR6) -> 0 | AW6: =SUM(AT6:AV6) -> 0 | AX6: Nivel (Lte Provincial)(Cruce A Piedra Alta) - La Ese (Escuela) | AY6: 10/14 | AZ6: 05/17 | BA6: 50.0 | BB6: 0 | BC6: 4 | BD6: =IF(BC6=1,"Llano (Pendientes naturales del terreno entre 0 y 5%)",IF(AND(BC6=2),"Algo Ondulado (Pendientes naturales del terreno entre 6 y 14%)",IF(AND(BC6=3),"Muy Ondulado (Pendientes naturales del terreno entre 15 y 25%)",IF(AND(BC6=4),"Montañoso (Pendientes naturales del terreno mayores a 25%)")))) -> Montañoso (Pendientes naturales del terreno mayores a 25%) | BE6: 1 | BF6: =VLOOKUP(BE6,'Códigos 2'!$A$1:$B$12,2,FALSE) -> Carpeta Asfáltica (CA) | BG6: 2 | BH6: 6.2 | BI6: 0 | BJ6: =IF(BI6=0,"No existe",IF(AND(BI6=1),"Pavimentado",IF(AND(BI6=2),"Mejorado",IF(AND(BI6=3),"Tierra")))) -> No existe | BK6: 0 | BL6: 50 | BM6: 1838 | BN6: 3 | BO6: =IF(BN6=5,"Alineamiento recto o con curvas tan suaves que no exigen una reducción significativa en la velocidad promedio normal de recorrido.",IF(AND(BN6=4),"Alineamiento con algunas curvas que exigen una reducción significativa en la velocidad promedio de circulación.",IF(AND(BN6=3),"Alineamiento algo sinuoso, pero con curvas cerradas que son aparentes y consistentes con las gradientes y las demás características del camino y del terreno que se atraviesa.",IF(AND(BN6=2),"Curvas cerradas frecuentes y, por lo general, inconsistentes con el terreno y la clase de carretera.",IF(AND(BN6=1),"Alineamiento muy sinuoso en todo el tramo, condición que admite solamente una velocidad de circulación muy baja."))))) -> Alineamiento algo sinuoso, pero con curvas cerradas que son aparentes y consistentes con las gradientes y las demás características del camino y del terreno que se atraviesa. | BP6: 1 | BQ6: =IF(BP6=5,"Pendientes menores del 3% en todo el tramo.",IF(AND(BP6=4),"Pendientes generalmente menores del 3% pero con algunas cuestas de corta longitud de hasta el 5%.",IF(AND(BP6=3),"Pendientes generalmente entre 3 y 6%, pero con una rasante ondulada y, consecuentemente, con tramos cortos de subida fuerte.",IF(AND(BP6=2),"Pendientes sostenidas entre 5 y 8% sobre una buena parte del tramo, condición que afecta en forma marcada la velocidad de recorrido y, cuando hay bastante tránsito, provoca frecuentes colas de vehículos detrás de los vehículos pesados.",IF(AND(BP6=1),"Pendientes sostenidas en exceso del 7% en casi todo el tramo. "))))) -> Pendientes sostenidas en exceso del 7% en casi todo el tramo. | BR6: 1 | BS6: 0 | BT6: =IF(BS6=5,"Superficie de los espaldones firme y regular, y donde se puede utilizar el ancho como fue construido originalmente.",IF(AND(BS6=4),"Superficie generalmente firme y utilizable en todo tiempo, pero con algunos tramos cortos en que el ancho inicial ha sido reducido por erosión u otras causas.",IF(AND(BS6=3),"Superficie erosionada o con baches profundos sobre una buena parte de la subsección, de manera que se inhibe el uso de los espaldones en la debida forma en esa parte.",IF(AND(BS6=2),"Superficie erosionada o con baches profundos, o el ancho transitable de los espaldones reducido sustancialmente, en casi toda la subsección.",IF(AND(BS6=1),"Se encuentra un desnivel peligroso entre el borde del pavimento y el espaldón, o la superficie está muy erosionada, con baches profundos o material suelto, o el ancho muy reducido del original."))))) -> FALSE | BU6: 5 | BV6: =IF(BU6=5,"Las señales son completamente adecuadas en número y ubicación, ",IF(AND(BU6=4),"El señalamiento es bastante completo, faltando solamente algunas señales de guía para los usuarios que no conocen la ruta.",IF(AND(BU6=3),"El señalamiento es regular en cuanto a cantidad y ubicación, siendo notable la falta de algunas señales de precaución y de guía.",IF(AND(BU6=2),"Existen muy pocas señales",IF(AND(BU6=1),"No existen señales o son tan inadecuadas, que no proveen información útil al conductor."))))) -> Las señales son completamente adecuadas en número y ubicación, | BW6: 4 | BX6: =IF(BW6=5,"Todas las alcantarillas y cunetas están bastante limpias y funcionan debidamente.",IF(AND(BW6=4),"La mayoría de las alcantarillas y cunetas aparentemente funcionan bien, pero existen indicaciones en algunos sitios de que el agua se estanca.",IF(AND(BW6=3),"Parece que algunas alcantarillas o cunetas no tienen capacidad hidráulica suficiente, por la erosión o socavación aparente.",IF(AND(BW6=2),"Parece que la mayoría de las alcantarillas y cunetas son inadecuadas; o hay vados en varios sitios en vez de estructuras de drenaje.",IF(AND(BW6=1),"El agua escurre por la calzada durante períodos de lluvia sobre una buena parte de la sub-sección y no existen cunetas longitudinales definidas; las estructuras de drenaje no existen, o son completamente inadecuadas."))))) -> La mayoría de las alcantarillas y cunetas aparentemente funcionan bien, pero existen indicaciones en algunos sitios de que el agua se estanca. | BY6: 5 | BZ6: =IF(BY6=5,"Superficie lisa, sin baches ni irregularidades notables.",IF(AND(BY6=4),"Superficie generalmente lisa, pero con unas pequeñas corrugaciones u otras irregularidades aisladas, o con baches pequeños superficiales.",IF(AND(BY6=3),"Superficie con frecuentes baches o irregularidades .",IF(AND(BY6=2),"Superficie muy irregular o con baches extensos y frecuentes (o material suelto, en caso de superficies no pavimentadas).",IF(AND(BY6=1),"Superficie muy deteriorada o irregular (o material suelto), hasta tal grado, en casi todo el tramo."))))) -> Superficie lisa, sin baches ni irregularidades notables. | CA6: 5 | CB6: =IF(CA6=5,"No existen evidencias de fallas en la estructura del pavimento, con la posible excepción de algunas en la superficie de ruedo.",IF(AND(CA6=4),"Existen huellas o corrugaciones que se derivan por debajo de la superficie de ruedo, pero que son aisladas y de poca extensión.",IF(AND(CA6=3),"Existen deformaciones u otras fallas de consideración sobre una buena parte de la subsección y, aunque no son extensas todavía, parece que siguen extendiéndose.",IF(AND(CA6=2),"Existen deformaciones u otras fallas de consideración sobre la mayor parte del tramo.",IF(AND(CA6=1),"Existen corrugaciones o huellas profundas sobre casi toda la faja de ruedo del tramo, hasta tal grado que no sería factible corregir la falla de la estructura, sino que se tendría que reconstruirla completamente."))))) -> No existen evidencias de fallas en la estructura del pavimento, con la posible excepción de algunas en la superficie de ruedo. | CC6: =(K6*BM6)*365/1000000 -> 17.549959 | CD6: 741 | CE6: 7 | CF6: ESCUELA DE LA ESE
A7: 17 | B7: 10030 | C7: 1 | D7: 1 | E7: 17 | F7: 3 | G7: 2 | H7: =IF(G7<100,"Primaria",IF(AND(G7>39,G7<300),"Secundaria",IF(AND(G7>299),"Terciaria"))) -> Primaria | I7: 1 | J7: =IF(I7=1,"Red de Alta Capacidad",IF(AND(I7=2),"Distribuidores Regionales",IF(AND(I7=3),"Conectores de Integración Territorial",IF(AND(I7=4),"Red Básica de Accesso")))) -> Red de Alta Capacidad | K7: =P7+$T7+$X7+$AB7+$AG7+$AK7+$AW7+AO7+AS7 -> 12.47 | L7: =L6+K7 -> 81.72 | P7: =SUM(M7:O7) -> 0 | Q7: 12.47 | T7: =SUM(Q7:S7) -> 12.47 | X7: =U7+V7+W7 -> 0 | AB7: =Y7+Z7+AA7 -> 0 | AC7: =T7+X7+AB7 -> 12.47 | AG7: =SUM(AD7:AF7) -> 0 | AK7: =SUM(AH7:AJ7) -> 0 | AO7: =SUM(AL7:AN7) -> 0 | AS7: =SUM(AP7:AR7) -> 0 | AW7: =SUM(AT7:AV7) -> 0 | AX7: Ojo De Agua(Cruce Providencia)- Cerro Asunción(Lte Prov) | AY7: 10/14 | AZ7: 07/15 | BA7: 50.0 | BB7: 0 | BC7: 4 | BD7: =IF(BC7=1,"Llano (Pendientes naturales del terreno entre 0 y 5%)",IF(AND(BC7=2),"Algo Ondulado (Pendientes naturales del terreno entre 6 y 14%)",IF(AND(BC7=3),"Muy Ondulado (Pendientes naturales del terreno entre 15 y 25%)",IF(AND(BC7=4),"Montañoso (Pendientes naturales del terreno mayores a 25%)")))) -> Montañoso (Pendientes naturales del terreno mayores a 25%) | BE7: 1 | BF7: =VLOOKUP(BE7,'Códigos 2'!$A$1:$B$12,2,FALSE) -> Carpeta Asfáltica (CA) | BG7: 2 | BH7: 6.3 | BI7: 0 | BJ7: =IF(BI7=0,"No existe",IF(AND(BI7=1),"Pavimentado",IF(AND(BI7=2),"Mejorado",IF(AND(BI7=3),"Tierra")))) -> No existe | BK7: 0 | BL7: 50 | BM7: 2135 | BN7: 3 | BO7: =IF(BN7=5,"Alineamiento recto o con curvas tan suaves que no exigen una reducción significativa en la velocidad promedio normal de recorrido.",IF(AND(BN7=4),"Alineamiento con algunas curvas que exigen una reducción significativa en la velocidad promedio de circulación.",IF(AND(BN7=3),"Alineamiento algo sinuoso, pero con curvas cerradas que son aparentes y consistentes con las gradientes y las demás características del camino y del terreno que se atraviesa.",IF(AND(BN7=2),"Curvas cerradas frecuentes y, por lo general, inconsistentes con el terreno y la clase de carretera.",IF(AND(BN7=1),"Alineamiento muy sinuoso en todo el tramo, condición que admite solamente una velocidad de circulación muy baja."))))) -> Alineamiento algo sinuoso, pero con curvas cerradas que son aparentes y consistentes con las gradientes y las demás características del camino y del terreno que se atraviesa. | BP7: 2 | BQ7: =IF(BP7=5,"Pendientes menores del 3% en todo el tramo.",IF(AND(BP7=4),"Pendientes generalmente menores del 3% pero con algunas cuestas de corta longitud de hasta el 5%.",IF(AND(BP7=3),"Pendientes generalmente entre 3 y 6%, pero con una rasante ondulada y, consecuentemente, con tramos cortos de subida fuerte.",IF(AND(BP7=2),"Pendientes sostenidas entre 5 y 8% sobre una buena parte del tramo, condición que afecta en forma marcada la velocidad de recorrido y, cuando hay bastante tránsito, provoca frecuentes colas de vehículos detrás de los vehículos pesados.",IF(AND(BP7=1),"Pendientes sostenidas en exceso del 7% en casi todo el tramo. "))))) -> Pendientes sostenidas entre 5 y 8% sobre una buena parte del tramo, condición que afecta en forma marcada la velocidad de recorrido y, cuando hay bastante tránsito, provoca frecuentes colas de vehículos detrás de los vehículos pesados. | BR7: 1 | BS7: 4 | BT7: =IF(BS7=5,"Superficie de los espaldones firme y regular, y donde se puede utilizar el ancho como fue construido originalmente.",IF(AND(BS7=4),"Superficie generalmente firme y utilizable en todo tiempo, pero con algunos tramos cortos en que el ancho inicial ha sido reducido por erosión u otras causas.",IF(AND(BS7=3),"Superficie erosionada o con baches profundos sobre una buena parte de la subsección, de manera que se inhibe el uso de los espaldones en la debida forma en esa parte.",IF(AND(BS7=2),"Superficie erosionada o con baches profundos, o el ancho transitable de los espaldones reducido sustancialmente, en casi toda la subsección.",IF(AND(BS7=1),"Se encuentra un desnivel peligroso entre el borde del pavimento y el espaldón, o la superficie está muy erosionada, con baches profundos o material suelto, o el ancho muy reducido del original."))))) -> Superficie generalmente firme y utilizable en todo tiempo, pero con algunos tramos cortos en que el ancho inicial ha sido reducido por erosión u otras causas. | BU7: 3 | BV7: =IF(BU7=5,"Las señales son completamente adecuadas en número y ubicación, ",IF(AND(BU7=4),"El señalamiento es bastante completo, faltando solamente algunas señales de guía para los usuarios que no conocen la ruta.",IF(AND(BU7=3),"El señalamiento es regular en cuanto a cantidad y ubicación, siendo notable la falta de algunas señales de precaución y de guía.",IF(AND(BU7=2),"Existen muy pocas señales",IF(AND(BU7=1),"No existen señales o son tan inadecuadas, que no proveen información útil al conductor."))))) -> El señalamiento es regular en cuanto a cantidad y ubicación, siendo notable la falta de algunas señales de precaución y de guía. | BW7: 4 | BX7: =IF(BW7=5,"Todas las alcantarillas y cunetas están bastante limpias y funcionan debidamente.",IF(AND(BW7=4),"La mayoría de las alcantarillas y cunetas aparentemente funcionan bien, pero existen indicaciones en algunos sitios de que el agua se estanca.",IF(AND(BW7=3),"Parece que algunas alcantarillas o cunetas no tienen capacidad hidráulica suficiente, por la erosión o socavación aparente.",IF(AND(BW7=2),"Parece que la mayoría de las alcantarillas y cunetas son inadecuadas; o hay vados en varios sitios en vez de estructuras de drenaje.",IF(AND(BW7=1),"El agua escurre por la calzada durante períodos de lluvia sobre una buena parte de la sub-sección y no existen cunetas longitudinales definidas; las estructuras de drenaje no existen, o son completamente inadecuadas."))))) -> La mayoría de las alcantarillas y cunetas aparentemente funcionan bien, pero existen indicaciones en algunos sitios de que el agua se estanca. | BY7: 5 | BZ7: =IF(BY7=5,"Superficie lisa, sin baches ni irregularidades notables.",IF(AND(BY7=4),"Superficie generalmente lisa, pero con unas pequeñas corrugaciones u otras irregularidades aisladas, o con baches pequeños superficiales.",IF(AND(BY7=3),"Superficie con frecuentes baches o irregularidades .",IF(AND(BY7=2),"Superficie muy irregular o con baches extensos y frecuentes (o material suelto, en caso de superficies no pavimentadas).",IF(AND(BY7=1),"Superficie muy deteriorada o irregular (o material suelto), hasta tal grado, en casi todo el tramo."))))) -> Superficie lisa, sin baches ni irregularidades notables. | CA7: 5 | CB7: =IF(CA7=5,"No existen evidencias de fallas en la estructura del pavimento, con la posible excepción de algunas en la superficie de ruedo.",IF(AND(CA7=4),"Existen huellas o corrugaciones que se derivan por debajo de la superficie de ruedo, pero que son aisladas y de poca extensión.",IF(AND(CA7=3),"Existen deformaciones u otras fallas de consideración sobre una buena parte de la subsección y, aunque no son extensas todavía, parece que siguen extendiéndose.",IF(AND(CA7=2),"Existen deformaciones u otras fallas de consideración sobre la mayor parte del tramo.",IF(AND(CA7=1),"Existen corrugaciones o huellas profundas sobre casi toda la faja de ruedo del tramo, hasta tal grado que no sería factible corregir la falla de la estructura, sino que se tendría que reconstruirla completamente."))))) -> No existen evidencias de fallas en la estructura del pavimento, con la posible excepción de algunas en la superficie de ruedo. | CC7: =(K7*BM7)*365/1000000 -> 9.7175593
A8: 14 | B8: 10041 | C8: 1 | D8: 1 | E8: 3 | F8: 8 | G8: 2 | H8: =IF(G8<100,"Primaria",IF(AND(G8>39,G8<300),"Secundaria",IF(AND(G8>299),"Terciaria"))) -> Primaria | I8: 1 | J8: =IF(I8=1,"Red de Alta Capacidad",IF(AND(I8=2),"Distribuidores Regionales",IF(AND(I8=3),"Conectores de Integración Territorial",IF(AND(I8=4),"Red Básica de Accesso")))) -> Red de Alta Capacidad | K8: =P8+$T8+$X8+$AB8+$AG8+$AK8+$AW8+AO8+AS8 -> 4.695 | L8: =L7+K8 -> 86.415 | P8: =SUM(M8:O8) -> 0 | Q8: 4.695 | T8: =SUM(Q8:S8) -> 4.695 | X8: =U8+V8+W8 -> 0 | AB8: =Y8+Z8+AA8 -> 0 | AC8: =T8+X8+AB8 -> 4.695 | AG8: =SUM(AD8:AF8) -> 0 | AK8: =SUM(AH8:AJ8) -> 0 | AO8: =SUM(AL8:AN8) -> 0 | AS8: =SUM(AP8:AR8) -> 0 | AW8: =SUM(AT8:AV8) -> 0 | AX8: Casa Mata (Ruta 406)(Lte. Prov) - La Sierra (R. 222) | AY8: 10/14 | AZ8: 03/15 | BA8: 50.0 | BB8: 0 | BC8: 4 | BD8: =IF(BC8=1,"Llano (Pendientes naturales del terreno entre 0 y 5%)",IF(AND(BC8=2),"Algo Ondulado (Pendientes naturales del terreno entre 6 y 14%)",IF(AND(BC8=3),"Muy Ondulado (Pendientes naturales del terreno entre 15 y 25%)",IF(AND(BC8=4),"Montañoso (Pendientes naturales del terreno mayores a 25%)")))) -> Montañoso (Pendientes naturales del terreno mayores a 25%) | BE8: 1 | BF8: =VLOOKUP(BE8,'Códigos 2'!$A$1:$B$12,2,FALSE) -> Carpeta Asfáltica (CA) | BG8: 2 | BH8: 6.7 | BI8: 0 | BJ8: =IF(BI8=0,"No existe",IF(AND(BI8=1),"Pavimentado",IF(AND(BI8=2),"Mejorado",IF(AND(BI8=3),"Tierra")))) -> No existe | BK8: 0 | BL8: 50 | BN8: 3 | BO8: =IF(BN8=5,"Alineamiento recto o con curvas tan suaves que no exigen una reducción significativa en la velocidad promedio normal de recorrido.",IF(AND(BN8=4),"Alineamiento con algunas curvas que exigen una reducción significativa en la velocidad promedio de circulación.",IF(AND(BN8=3),"Alineamiento algo sinuoso, pero con curvas cerradas que son aparentes y consistentes con las gradientes y las demás características del camino y del terreno que se atraviesa.",IF(AND(BN8=2),"Curvas cerradas frecuentes y, por lo general, inconsistentes con el terreno y la clase de carretera.",IF(AND(BN8=1),"Alineamiento muy sinuoso en todo el tramo, condición que admite solamente una velocidad de circulación muy baja."))))) -> Alineamiento algo sinuoso, pero con curvas cerradas que son aparentes y consistentes con las gradientes y las demás características del camino y del terreno que se atraviesa. | BP8: 2 | BQ8: =IF(BP8=5,"Pendientes menores del 3% en todo el tramo.",IF(AND(BP8=4),"Pendientes generalmente menores del 3% pero con algunas cuestas de corta longitud de hasta el 5%.",IF(AND(BP8=3),"Pendientes generalmente entre 3 y 6%, pero con una rasante ondulada y, consecuentemente, con tramos cortos de subida fuerte.",IF(AND(BP8=2),"Pendientes sostenidas entre 5 y 8% sobre una buena parte del tramo, condición que afecta en forma marcada la velocidad de recorrido y, cuando hay bastante tránsito, provoca frecuentes colas de vehículos detrás de los vehículos pesados.",IF(AND(BP8=1),"Pendientes sostenidas en exceso del 7% en casi todo el tramo. "))))) -> Pendientes sostenidas entre 5 y 8% sobre una buena parte del tramo, condición que afecta en forma marcada la velocidad de recorrido y, cuando hay bastante tránsito, provoca frecuentes colas de vehículos detrás de los vehículos pesados. | BR8: 1 | BS8: 0 | BT8: =IF(BS8=5,"Superficie de los espaldones firme y regular, y donde se puede utilizar el ancho como fue construido originalmente.",IF(AND(BS8=4),"Superficie generalmente firme y utilizable en todo tiempo, pero con algunos tramos cortos en que el ancho inicial ha sido reducido por erosión u otras causas.",IF(AND(BS8=3),"Superficie erosionada o con baches profundos sobre una buena parte de la subsección, de manera que se inhibe el uso de los espaldones en la debida forma en esa parte.",IF(AND(BS8=2),"Superficie erosionada o con baches profundos, o el ancho transitable de los espaldones reducido sustancialmente, en casi toda la subsección.",IF(AND(BS8=1),"Se encuentra un desnivel peligroso entre el borde del pavimento y el espaldón, o la superficie está muy erosionada, con baches profundos o material suelto, o el ancho muy reducido del original."))))) -> FALSE | BU8: 5 | BV8: =IF(BU8=5,"Las señales son completamente adecuadas en número y ubicación, ",IF(AND(BU8=4),"El señalamiento es bastante completo, faltando solamente algunas señales de guía para los usuarios que no conocen la ruta.",IF(AND(BU8=3),"El señalamiento es regular en cuanto a cantidad y ubicación, siendo notable la falta de algunas señales de precaución y de guía.",IF(AND(BU8=2),"Existen muy pocas señales",IF(AND(BU8=1),"No existen señales o son tan inadecuadas, que no proveen información útil al conductor."))))) -> Las señales son completamente adecuadas en número y ubicación, | BW8: 4 | BX8: =IF(BW8=5,"Todas las alcantarillas y cunetas están bastante limpias y funcionan debidamente.",IF(AND(BW8=4),"La mayoría de las alcantarillas y cunetas aparentemente funcionan bien, pero existen indicaciones en algunos sitios de que el agua se estanca.",IF(AND(BW8=3),"Parece que algunas alcantarillas o cunetas no tienen capacidad hidráulica suficiente, por la erosión o socavación aparente.",IF(AND(BW8=2),"Parece que la mayoría de las alcantarillas y cunetas son inadecuadas; o hay vados en varios sitios en vez de estructuras de drenaje.",IF(AND(BW8=1),"El agua escurre por la calzada durante períodos de lluvia sobre una buena parte de la sub-sección y no existen cunetas longitudinales definidas; las estructuras de drenaje no existen, o son completamente inadecuadas."))))) -> La mayoría de las alcantarillas y cunetas aparentemente funcionan bien, pero existen indicaciones en algunos sitios de que el agua se estanca. | BY8: 5 | BZ8: =IF(BY8=5,"Superficie lisa, sin baches ni irregularidades notables.",IF(AND(BY8=4),"Superficie generalmente lisa, pero con unas pequeñas corrugaciones u otras irregularidades aisladas, o con baches pequeños superficiales.",IF(AND(BY8=3),"Superficie con frecuentes baches o irregularidades .",IF(AND(BY8=2),"Superficie muy irregular o con baches extensos y frecuentes (o material suelto, en caso de superficies no pavimentadas).",IF(AND(BY8=1),"Superficie muy deteriorada o irregular (o material suelto), hasta tal grado, en casi todo el tramo."))))) -> Superficie lisa, sin baches ni irregularidades notables. | CA8: 5 | CB8: =IF(CA8=5,"No existen evidencias de fallas en la estructura del pavimento, con la posible excepción de algunas en la superficie de ruedo.",IF(AND(CA8=4),"Existen huellas o corrugaciones que se derivan por debajo de la superficie de ruedo, pero que son aisladas y de poca extensión.",IF(AND(CA8=3),"Existen deformaciones u otras fallas de consideración sobre una buena parte de la subsección y, aunque no son extensas todavía, parece que siguen extendiéndose.",IF(AND(CA8=2),"Existen deformaciones u otras fallas de consideración sobre la mayor parte del tramo.",IF(AND(CA8=1),"Existen corrugaciones o huellas profundas sobre casi toda la faja de ruedo del tramo, hasta tal grado que no sería factible corregir la falla de la estructura, sino que se tendría que reconstruirla completamente."))))) -> No existen evidencias de fallas en la estructura del pavimento, con la posible excepción de algunas en la superficie de ruedo. | CC8: =(K8*BM8)*365/1000000 -> 0 | CD8: E.P.07 | CF8: CASAMATA(0+100 MTS DESPUES CRUCE SAN CRISTOBAL NORTE(R.406))
